Workbook

Sheet 1 TRIMESTRE
B1: Colaboradores - Innovatis
B2: NOME | C2: DATA DE ADMISSÃO | D2: JANEIRO | E2: FEVEREIRO | F2: MARÇO | G2: TRIMESTRE | H2: BONIFICAÇÃO (%) | I2: VALOR BONIFICAÇÃO
A3: 1 | B3: Alexandre Mariano | C3: 45505 | D3: 7500 | E3: 7500 | F3: 7500 | G3: =SUM('1 TRIMESTRE'!$D3:$F3) -> 22500 | H3: 0.18 | I3: ='1 TRIMESTRE'!$G3*'1 TRIMESTRE'!$H3 -> 4050
B4: Raissa Cartaxo | C4: 45733 | D4: 7500 | E4: 7500 | F4: 7500 | G4: =SUM('1 TRIMESTRE'!$D4:$F4) -> 22500 | H4: 0.25 | I4: ='1 TRIMESTRE'!$G4*'1 TRIMESTRE'!$H4 -> 5625
B5: Taís Santino | C5: 45614 | D5: 2500 | E5: 2500 | F5: 2500 | G5: =SUM('1 TRIMESTRE'!$D5:$F5) -> 7500 | H5: 0.18 | I5: ='1 TRIMESTRE'!$G5*'1 TRIMESTRE'!$H5 -> 1350
B6: Sthephanie Vilar | C6: 45173 | D6: 9500 | E6: 9500 | F6: 9500 | G6: =SUM('1 TRIMESTRE'!$D6:$F6) -> 28500 | H6: 0.25 | I6: ='1 TRIMESTRE'!$G6*'1 TRIMESTRE'!$H6 -> 7125
B7: Dayane Cavalcante | C7: 45306 | D7: 4500 | E7: 6000 | F7: 6000 | G7: =SUM('1 TRIMESTRE'!$D7:$F7) -> 16500 | H7: 0.18 | I7: ='1 TRIMESTRE'!$G7*'1 TRIMESTRE'!$H7 -> 2970
B8: Laryssa Costa | C8: 45391 | D8: 2500 | E8: 3500 | F8: 3500 | G8: =SUM('1 TRIMESTRE'!$D8:$F8) -> 9500 | H8: 0.18 | I8: ='1 TRIMESTRE'!$G8*'1 TRIMESTRE'!$H8 -> 1710
B9: Letícia Costa (bolsa de 1.200) | C9: 46091 | F9: 1200 | G9: =SUM('1 TRIMESTRE'!$D9:$F9) -> 1200 | H9: 0.18 | I9: ='1 TRIMESTRE'!$G9*'1 TRIMESTRE'!$H9 -> 216
A10: 24 | B10: Lucas Montenegro | C10: 44013 | D10: 9000 | E10: 9000 | F10: 9000 | G10: =SUM('1 TRIMESTRE'!$D10:$F10) -> 27000 | H10: 0.25 | I10: ='1 TRIMESTRE'!$G10*'1 TRIMESTRE'!$H10 -> 6750
A11: 29 | B11: Maria Clara | C11: 45251 | D11: 2500 | E11: 2500 | F11: 2500 | G11: =SUM('1 TRIMESTRE'!$D11:$F11) -> 7500 | H11: 0.18 | I11: ='1 TRIMESTRE'!$G11*'1 TRIMESTRE'!$H11 -> 1350
B12: Gabriel Matias | C12: 45839 | D12: 1200 | E12: 1200 | F12: 1200 | G12: =SUM('1 TRIMESTRE'!$D12:$F12) -> 3600 | H12: 0.18 | I12: ='1 TRIMESTRE'!$G12*'1 TRIMESTRE'!$H12 -> 648
A13: 20 | B13: Isabela Vanessa | C13: 45572 | D13: 3500 | E13: 3500 | F13: 3500 | G13: =SUM('1 TRIMESTRE'!$D13:$F13) -> 10500 | H13: 0.18 | I13: ='1 TRIMESTRE'!$G13*'1 TRIMESTRE'!$H13 -> 1890
A14: 26 | B14: Layze Lima | C14: 45327 | D14: 2600 | E14: 3500 | F14: 3500 | G14: =SUM('1 TRIMESTRE'!$D14:$F14) -> 9600 | H14: 0.18 | I14: ='1 TRIMESTRE'!$G14*'1 TRIMESTRE'!$H14 -> 1728
B15: Janailma Santos | C15: 45742 | D15: 6000 | E15: 7500 | F15: 7500 | G15: =SUM('1 TRIMESTRE'!$D15:$F15) -> 21000 | H15: 0.18 | I15: ='1 TRIMESTRE'!$G15*'1 TRIMESTRE'!$H15 -> 3780
B16: Érlon Gabriel | D16: 1200 | E16: 1200 | F16: 1200 | G16: =SUM('1 TRIMESTRE'!$D16:$F16) -> 3600 | H16: 0.18 | I16: ='1 TRIMESTRE'!$G16*'1 TRIMESTRE'!$H16 -> 648
B17: Tarcylla Kivia | C17: 46042 | D17: 917 | E17: 2500 | F17: 2500 | G17: =SUM('1 TRIMESTRE'!$D17:$F17) -> 5917 | H17: 0.18 | I17: ='1 TRIMESTRE'!$G17*'1 TRIMESTRE'!$H17 -> 1065.06 | J17: 1350
A18: 41 | B18: Larice Ferreira | D18: 4500 | E18: 4500 | F18: 4500 | G18: =SUM('1 TRIMESTRE'!$D18:$F18) -> 13500 | H18: 0.18 | I18: ='1 TRIMESTRE'!$G18*'1 TRIMESTRE'!$H18 -> 2430
A19: 5 | B19: Andrea Albuquerque | C19: 45847 | D19: 7500 | E19: 7500 | F19: 7500 | G19: =SUM('1 TRIMESTRE'!$D19:$F19) -> 22500 | H19: 0.25 | I19: ='1 TRIMESTRE'!$G19*'1 TRIMESTRE'!$H19 -> 5625 | J19: `
B20: Erlon Reydne | D20: 2500 | E20: 3500 | F20: 3500 | G20: =SUM('1 TRIMESTRE'!$D20:$F20) -> 9500 | H20: 0.18 | I20: ='1 TRIMESTRE'!$G20*'1 TRIMESTRE'!$H20 -> 1710
B21: Ítalo Oliveira (bolsa de 1.200) | C21: 46092 | F21: 1200 | G21: =SUM('1 TRIMESTRE'!$D21:$F21) -> 1200 | H21: 0.18 | I21: ='1 TRIMESTRE'!$G21*'1 TRIMESTRE'!$H21 -> 216
A22: 16 | B22: Gabriel - Marketing | D22: 3000 | G22: =SUM('1 TRIMESTRE'!$D22:$F22) -> 3000 | H22: 0.18 | I22: ='1 TRIMESTRE'!$G22*'1 TRIMESTRE'!$H22 -> 540
B23: David Lopes | C23: 46028 | D23: 4500 | E23: 4500 | F23: 4500 | G23: =SUM('1 TRIMESTRE'!$D23:$F23) -> 13500 | H23: 0.18 | I23: ='1 TRIMESTRE'!$G23*'1 TRIMESTRE'!$H23 -> 2430
A24: 12 | B24: Gabriel Queiroz | C24: 45817 | D24: 3000 | E24: 3000 | F24: 3000 | G24: =SUM('1 TRIMESTRE'!$D24:$F24) -> 9000 | H24: 0.18 | I24: ='1 TRIMESTRE'!$G24*'1 TRIMESTRE'!$H24 -> 1620
A25: 19 | B25: Heitor Neto | C25: 45870 | D25: 7500 | E25: 7500 | F25: 7500 | G25: =SUM('1 TRIMESTRE'!$D25:$F25) -> 22500 | H25: 0.25 | I25: ='1 TRIMESTRE'!$G25*'1 TRIMESTRE'!$H25 -> 5625
A26: 37 | B26: Victor Eduardo | C26: 45251 | D26: 3000 | E26: 3000 | F26: 3000 | G26: =SUM('1 TRIMESTRE'!$D26:$F26) -> 9000 | H26: 0.18 | I26: ='1 TRIMESTRE'!$G26*'1 TRIMESTRE'!$H26 -> 1620
A27: 23 | B27: Gabriel Chaves | C27: 45940 | D27: 3500 | E27: 3500 | F27: 3500 | G27: =SUM('1 TRIMESTRE'!$D27:$F27) -> 10500 | H27: 0.18 | I27: ='1 TRIMESTRE'!$G27*'1 TRIMESTRE'!$H27 -> 1890
B28: Samuel Araújo (bolsa de 1.200) | C28: 46100 | F28: 600 | G28: =SUM('1 TRIMESTRE'!$D28:$F28) -> 600 | H28: 0.18 | I28: ='1 TRIMESTRE'!$G28*'1 TRIMESTRE'!$H28 -> 108
A29: 42 | B29: Yarimma Karol | C29: 46023 | D29: 5000 | E29: 6000 | F29: 6000 | G29: =SUM('1 TRIMESTRE'!$D29:$F29) -> 17000 | H29: 0.18 | I29: ='1 TRIMESTRE'!$G29*'1 TRIMESTRE'!$H29 -> 3060
A30: 43 | B30: Camila Ramos (bolsa de 10.000) | C30: 46104 | F30: 2903 | G30: =SUM('1 TRIMESTRE'!$D30:$F30) -> 2903 | H30: 0.18 | I30: ='1 TRIMESTRE'!$G30*'1 TRIMESTRE'!$H30 -> 522.54
G31: =SUM('1 TRIMESTRE'!$D31:$F31) -> 0 | I31: ='1 TRIMESTRE'!$G31*'1 TRIMESTRE'!$H31 -> 0
B32: Danniela da Silva Carvalho | C32: 46048 | D32: 417 | E32: 2500 | F32: 2500 | G32: =SUM('1 TRIMESTRE'!$D32:$F32) -> 5417 | H32: 0.18 | I32: ='1 TRIMESTRE'!$G32*'1 TRIMESTRE'!$H32 -> 975.06 | J32: 1350
B33: Kriscia Jheniffer Gomes Ribeiro | C33: 45931 | G33: =SUM('1 TRIMESTRE'!$D33:$F33) -> 0 | H33: 0.18 | I33: ='1 TRIMESTRE'!$G33*'1 TRIMESTRE'!$H33 -> 0
B34: Thaiane Ximenes dos Santos | C34: 45717 | G34: =SUM('1 TRIMESTRE'!$D34:$F34) -> 0 | H34: 0.18 | I34: ='1 TRIMESTRE'!$G34*'1 TRIMESTRE'!$H34 -> 0
I35: =SUM(I3:I34) -> 69276.66

Sheet 2 TRIMESTRE
B1: Colaboradores - Innovatis
B2: NOME | C2: DATA DE ADMISSÃO | D2: ABRIL | E2: MAIO | F2: JUNHO | G2: TRIMESTRE | H2: BONIFICAÇÃO (%) | I2: VALOR BONIFICAÇÃO
A3: 1 | B3: Alexandre Mariano | C3: 45505 | D3: 7500 | E3: 7500 | F3: 7500 | G3: =SUM('2 TRIMESTRE'!$D3:$F3) -> 22500 | H3: 0.15 | I3: ='2 TRIMESTRE'!$G3*'2 TRIMESTRE'!$H3 -> 3375
B4: Raissa Cartaxo | C4: 45733 | D4: 7500 | E4: 7500 | F4: 7500 | G4: =SUM('2 TRIMESTRE'!$D4:$F4) -> 22500 | H4: 0.25 | I4: ='2 TRIMESTRE'!$G4*'2 TRIMESTRE'!$H4 -> 5625
B5: Taís Santino | C5: 45614 | D5: 2500 | E5: 2500 | F5: 2500 | G5: =SUM('2 TRIMESTRE'!$D5:$F5) -> 7500 | H5: 0.15 | I5: ='2 TRIMESTRE'!$G5*'2 TRIMESTRE'!$H5 -> 1125
B6: Sthephanie Vilar | C6: 45173 | D6: 9500 | E6: 9500 | F6: 9500 | G6: =SUM('2 TRIMESTRE'!$D6:$F6) -> 28500 | H6: 0.25 | I6: ='2 TRIMESTRE'!$G6*'2 TRIMESTRE'!$H6 -> 7125
B7: Dayane Cavalcante | C7: 45306 | D7: 6000 | E7: 6000 | F7: 6000 | G7: =SUM('2 TRIMESTRE'!$D7:$F7) -> 18000 | H7: 0.15 | I7: ='2 TRIMESTRE'!$G7*'2 TRIMESTRE'!$H7 -> 2700
B8: Laryssa Costa | C8: 45391 | D8: 3500 | E8: 3500 | F8: 3500 | G8: =SUM('2 TRIMESTRE'!$D8:$F8) -> 10500 | H8: 0.15 | I8: ='2 TRIMESTRE'!$G8*'2 TRIMESTRE'!$H8 -> 1575
B9: Letícia Costa (bolsa de 1.200) | C9: 46091 | D9: 1200 | E9: 1200 | F9: 1200 | G9: =SUM('2 TRIMESTRE'!$D9:$F9) -> 3600 | H9: 0.15 | I9: ='2 TRIMESTRE'!$G9*'2 TRIMESTRE'!$H9 -> 540
A10: 24 | B10: Lucas Montenegro | C10: 44013 | D10: 9000 | E10: 9000 | F10: 9000 | G10: =SUM('2 TRIMESTRE'!$D10:$F10) -> 27000 | H10: 0.25 | I10: ='2 TRIMESTRE'!$G10*'2 TRIMESTRE'!$H10 -> 6750
A11: 29 | B11: Maria Clara | C11: 45251 | D11: 2667 | E11: 3500 | F11: 3500 | G11: =SUM('2 TRIMESTRE'!$D11:$F11) -> 9667 | H11: 0.15 | I11: ='2 TRIMESTRE'!$G11*'2 TRIMESTRE'!$H11 -> 1450.05
B12: Gabriel Matias | C12: 45839 | D12: 1200 | E12: 1200 | F12: 1200 | G12: =SUM('2 TRIMESTRE'!$D12:$F12) -> 3600 | H12: 0.15 | I12: ='2 TRIMESTRE'!$G12*'2 TRIMESTRE'!$H12 -> 540
A13: 20 | B13: Isabela Vanessa | C13: 45572 | D13: 3500 | E13: 3500 | F13: 3500 | G13: =SUM('2 TRIMESTRE'!$D13:$F13) -> 10500 | H13: 0.15 | I13: ='2 TRIMESTRE'!$G13*'2 TRIMESTRE'!$H13 -> 1575
A14: 26 | B14: Layze Lima | C14: 45327 | D14: 3500 | E14: 3500 | F14: 3500 | G14: =SUM('2 TRIMESTRE'!$D14:$F14) -> 10500 | H14: 0.15 | I14: ='2 TRIMESTRE'!$G14*'2 TRIMESTRE'!$H14 -> 1575
B15: Janailma Santos | C15: 45742 | D15: 7500 | E15: 7500 | F15: 7500 | G15: =SUM('2 TRIMESTRE'!$D15:$F15) -> 22500 | H15: 0.15 | I15: ='2 TRIMESTRE'!$G15*'2 TRIMESTRE'!$H15 -> 3375
B16: Tarcylla Kivia | C16: 46042 | D16: 2500 | E16: 2500 | F16: 2500 | G16: =SUM('2 TRIMESTRE'!$D16:$F16) -> 7500 | H16: 0.15 | I16: ='2 TRIMESTRE'!$G16*'2 TRIMESTRE'!$H16 -> 1125
A17: 5 | B17: Andrea Albuquerque | C17: 45847 | D17: 7500 | E17: 7500 | F17: 7500 | G17: =SUM('2 TRIMESTRE'!$D17:$F17) -> 22500 | H17: 0.25 | I17: ='2 TRIMESTRE'!$G17*'2 TRIMESTRE'!$H17 -> 5625
B18: Ítalo Oliveira (bolsa de 1.200) | C18: 46092 | D18: 1200 | E18: 1200 | F18: 1200 | G18: =SUM('2 TRIMESTRE'!$D18:$F18) -> 3600 | H18: 0.15 | I18: ='2 TRIMESTRE'!$G18*'2 TRIMESTRE'!$H18 -> 540
A19: 16 | B19: Gabriel - Marketing | D19: 3000 | G19: =SUM('2 TRIMESTRE'!$D19:$F19) -> 3000 | H19: 0.15 | I19: ='2 TRIMESTRE'!$G19*'2 TRIMESTRE'!$H19 -> 450
B20: David Lopes | C20: 46028 | D20: 4500 | E20: 4500 | F20: 4500 | G20: =SUM('2 TRIMESTRE'!$D20:$F20) -> 13500 | H20: 0.15 | I20: ='2 TRIMESTRE'!$G20*'2 TRIMESTRE'!$H20 -> 2025
A21: 12 | B21: Gabriel Queiroz | C21: 45817 | D21: 3000 | E21: 3000 | F21: 3000 | G21: =SUM('2 TRIMESTRE'!$D21:$F21) -> 9000 | H21: 0.15 | I21: ='2 TRIMESTRE'!$G21*'2 TRIMESTRE'!$H21 -> 1350
A22: 19 | B22: Heitor Neto | C22: 45870 | D22: 7500 | E22: 7500 | F22: 7500 | G22: =SUM('2 TRIMESTRE'!$D22:$F22) -> 22500 | H22: 0.25 | I22: ='2 TRIMESTRE'!$G22*'2 TRIMESTRE'!$H22 -> 5625
A23: 37 | B23: Victor Eduardo | C23: 45251 | D23: 3500 | E23: 3500 | F23: 3500 | G23: =SUM('2 TRIMESTRE'!$D23:$F23) -> 10500 | H23: 0.15 | I23: ='2 TRIMESTRE'!$G23*'2 TRIMESTRE'!$H23 -> 1575
A24: 23 | B24: Gabriel Chaves | C24: 45940 | D24: 4500 | E24: 4500 | F24: 4500 | G24: =SUM('2 TRIMESTRE'!$D24:$F24) -> 13500 | H24: 0.15 | I24: ='2 TRIMESTRE'!$G24*'2 TRIMESTRE'!$H24 -> 2025
B25: Samuel Araújo (bolsa de 1.200) | C25: 46100 | D25: 1200 | E25: 1200 | F25: 1200 | G25: =SUM('2 TRIMESTRE'!$D25:$F25) -> 3600 | H25: 0.15 | I25: ='2 TRIMESTRE'!$G25*'2 TRIMESTRE'!$H25 -> 540
A26: 42 | B26: Yarimma Karol | C26: 46023 | D26: 6000 | E26: 6000 | F26: 6000 | G26: =SUM('2 TRIMESTRE'!$D26:$F26) -> 18000 | H26: 0.15 | I26: ='2 TRIMESTRE'!$G26*'2 TRIMESTRE'!$H26 -> 2700
A27: 43 | B27: Camila Ramos (bolsa de 10.000) | C27: 46104 | D27: 10000 | E27: 10000 | F27: 10000 | G27: =SUM('2 TRIMESTRE'!$D27:$F27) -> 30000 | H27: 0.15 | I27: ='2 TRIMESTRE'!$G27*'2 TRIMESTRE'!$H27 -> 4500
G28: =SUM('2 TRIMESTRE'!$D28:$F28) -> 0 | I28: ='2 TRIMESTRE'!$G28*'2 TRIMESTRE'!$H28 -> 0
B29: Danniela da Silva Carvalho | C29: 46048 | D29: 2500 | E29: 2500 | F29: 2500 | G29: =SUM('2 TRIMESTRE'!$D29:$F29) -> 7500 | H29: 0.15 | I29: ='2 TRIMESTRE'!$G29*'2 TRIMESTRE'!$H29 -> 1125
B30: Ana Carolina Galdino Aniceto | C30: 46125 | D30: =18*40 -> 720 | E30: 1200 | F30: 1200 | G30: =SUM('2 TRIMESTRE'!$D30:$F30) -> 3120 | H30: 0.15 | I30: ='2 TRIMESTRE'!$G30*'2 TRIMESTRE'!$H30 -> 468
B31: Andre Luiz de Luna Guerra | C31: 46153 | D31: 0 | E31: 10500 | F31: 15000 | G31: =SUM('2 TRIMESTRE'!$D31:$F31) -> 25500 | H31: 0.15 | I31: ='2 TRIMESTRE'!$G31*'2 TRIMESTRE'!$H31 -> 3825
B32: José Iago Feitosa Muniz | C32: 46125 | D32: =18*40 -> 720 | E32: 1200 | F32: 1200 | G32: =SUM('2 TRIMESTRE'!$D32:$F32) -> 3120 | H32: 0.15 | I32: ='2 TRIMESTRE'!$G32*'2 TRIMESTRE'!$H32 -> 468
B33: José Nunes Damacena Neto | C33: 46174 | D33: 0 | E33: 6000 | F33: 6000 | G33: =SUM('2 TRIMESTRE'!$D33:$F33) -> 12000 | H33: 0.15 | I33: ='2 TRIMESTRE'!$G33*'2 TRIMESTRE'!$H33 -> 1800
B34: Livia dos Santos Falcão | C34: 46153 | D34: 0 | E34: 5600 | F34: 8000 | G34: =SUM('2 TRIMESTRE'!$D34:$F34) -> 13600 | H34: 0.15 | I34: ='2 TRIMESTRE'!$G34*'2 TRIMESTRE'!$H34 -> 2040
B35: Lívia Maria Dantas França | C35: 46135 | D35: =8*40 -> 320 | E35: 1200 | F35: 1200 | G35: =SUM('2 TRIMESTRE'!$D35:$F35) -> 2720 | H35: 0.15 | I35: ='2 TRIMESTRE'!$G35*'2 TRIMESTRE'!$H35 -> 408
B36: Lizandra Holanda de Araujo Sousa | C36: 46125 | D36: =18*40 -> 720 | E36: 1200 | F36: 1200 | G36: =SUM('2 TRIMESTRE'!$D36:$F36) -> 3120 | H36: 0.15 | I36: ='2 TRIMESTRE'!$G36*'2 TRIMESTRE'!$H36 -> 468
B37: Marcos Andrey de Lira Albuquerque | C37: 46125 | D37: =18*40 -> 720 | E37: 1200 | F37: 1200 | G37: =SUM('2 TRIMESTRE'!$D37:$F37) -> 3120 | H37: 0.15 | I37: ='2 TRIMESTRE'!$G37*'2 TRIMESTRE'!$H37 -> 468
B38: Maria Gabriela dos Santos Rodrigues | C38: 46148 | D38: 0 | E38: =25*40 -> 1000 | F38: 1200 | G38: =SUM('2 TRIMESTRE'!$D38:$F38) -> 2200 | H38: 0.15 | I38: ='2 TRIMESTRE'!$G38*'2 TRIMESTRE'!$H38 -> 330
B39: Nathan Meira Nóbrega | C39: 46181 | D39: 0 | E39: 0 | F39: =23*40 -> 920 | G39: =SUM('2 TRIMESTRE'!$D39:$F39) -> 920 | H39: 0.15 | I39: ='2 TRIMESTRE'!$G39*'2 TRIMESTRE'!$H39 -> 138
B40: Pedro Henrique Lins Queiroga de Castro | C40: 46134 | D40: =18*40 -> 720 | E40: 1200 | F40: 1200 | G40: =SUM('2 TRIMESTRE'!$D40:$F40) -> 3120 | H40: 0.15 | I40: ='2 TRIMESTRE'!$G40*'2 TRIMESTRE'!$H40 -> 468
...
